<?xml version="1.0"?>
<robot name="simple_humanoid">
  <!-- Materials -->
  <material name="blue">
    <color rgba="0 0 0.8 1"/>
  </material>
  <material name="white">
    <color rgba="1 1 1 1"/>
  </material>
  <material name="black">
    <color rgba="0 0 0 1"/>
  </material>

  <!-- Base link -->
  <link name="base_link">
    <visual>
      <geometry>
        <box size="0.3 0.2 0.5"/>
      </geometry>
      <material name="white"/>
    </visual>
    <collision>
      <geometry>
        <box size="0.3 0.2 0.5"/>
      </geometry>
    </collision>
    <inertial>
      <mass value="10.0"/>
      <inertia ixx="1.0" ixy="0" ixz="0" iyy="1.0" iyz="0" izz="1.0"/>
    </inertial>
  </link>

  <!-- Head -->
  <link name="head">
    <visual>
      <geometry>
        <sphere radius="0.1"/>
      </geometry>
      <material name="white"/>
    </visual>
    <collision>
      <geometry>
        <sphere radius="0.1"/>
      </geometry>
    </collision>
    <inertial>
      <mass value="2.0"/>
      <inertia ixx="0.008" ixy="0" ixz="0" iyy="0.008" iyz="0" izz="0.008"/>
    </inertial>
  </link>

  <joint name="neck_joint" type="revolute">
    <parent link="base_link"/>
    <child link="head"/>
    <origin xyz="0 0 0.35" rpy="0 0 0"/>
    <axis xyz="0 1 0"/>
    <limit lower="-0.5" upper="0.5" effort="10" velocity="1"/>
  </joint>

  <!-- Left Arm -->
  <link name="left_upper_arm">
    <visual>
      <geometry>
        <cylinder length="0.3" radius="0.05"/>
      </geometry>
      <material name="blue"/>
    </visual>
    <collision>
      <geometry>
        <cylinder length="0.3" radius="0.05"/>
      </geometry>
    </collision>
    <inertial>
      <mass value="1.0"/>
      <inertia ixx="0.01" ixy="0" ixz="0" iyy="0.01" iyz="0" izz="0.0025"/>
    </inertial>
  </link>

  <joint name="left_shoulder_joint" type="revolute">
    <parent link="base_link"/>
    <child link="left_upper_arm"/>
    <origin xyz="0.2 0 0.1" rpy="0 0 1.57"/>
    <axis xyz="0 1 0"/>
    <limit lower="-1.57" upper="1.57" effort="10" velocity="1"/>
  </joint>

  <link name="left_lower_arm">
    <visual>
      <geometry>
        <cylinder length="0.3" radius="0.04"/>
      </geometry>
      <material name="blue"/>
    </visual>
    <collision>
      <geometry>
        <cylinder length="0.3" radius="0.04"/>
      </geometry>
    </collision>
    <inertial>
      <mass value="0.8"/>
      <inertia ixx="0.008" ixy="0" ixz="0" iyy="0.008" iyz="0" izz="0.0016"/>
    </inertial>
  </link>

  <joint name="left_elbow_joint" type="revolute">
    <parent link="left_upper_arm"/>
    <child link="left_lower_arm"/>
    <origin xyz="0 0 -0.3" rpy="0 0 0"/>
    <axis xyz="0 1 0"/>
    <limit lower="-1.57" upper="1.57" effort="10" velocity="1"/>
  </joint>

  <!-- Right Arm (similar to left) -->
  <link name="right_upper_arm">
    <visual>
      <geometry>
        <cylinder length="0.3" radius="0.05"/>
      </geometry>
      <material name="blue"/>
    </visual>
    <collision>
      <geometry>
        <cylinder length="0.3" radius="0.05"/>
      </geometry>
    </collision>
    <inertial>
      <mass value="1.0"/>
      <inertia ixx="0.01" ixy="0" ixz="0" iyy="0.01" iyz="0" izz="0.0025"/>
    </inertial>
  </link>

  <joint name="right_shoulder_joint" type="revolute">
    <parent link="base_link"/>
    <child link="right_upper_arm"/>
    <origin xyz="-0.2 0 0.1" rpy="0 0 -1.57"/>
    <axis xyz="0 1 0"/>
    <limit lower="-1.57" upper="1.57" effort="10" velocity="1"/>
  </joint>

  <link name="right_lower_arm">
    <visual>
      <geometry>
        <cylinder length="0.3" radius="0.04"/>
      </geometry>
      <material name="blue"/>
    </visual>
    <collision>
      <geometry>
        <cylinder length="0.3" radius="0.04"/>
      </geometry>
    </collision>
    <inertial>
      <mass value="0.8"/>
      <inertia ixx="0.008" ixy="0" ixz="0" iyy="0.008" iyz="0" izz="0.0016"/>
    </inertial>
  </link>

  <joint name="right_elbow_joint" type="revolute">
    <parent link="right_upper_arm"/>
    <child link="right_lower_arm"/>
    <origin xyz="0 0 -0.3" rpy="0 0 0"/>
    <axis xyz="0 1 0"/>
    <limit lower="-1.57" upper="1.57" effort="10" velocity="1"/>
  </joint>

  <!-- Left Leg -->
  <link name="left_upper_leg">
    <visual>
      <geometry>
        <cylinder length="0.4" radius="0.06"/>
      </geometry>
      <material name="black"/>
    </visual>
    <collision>
      <geometry>
        <cylinder length="0.4" radius="0.06"/>
      </geometry>
    </collision>
    <inertial>
      <mass value="2.0"/>
      <inertia ixx="0.02" ixy="0" ixz="0" iyy="0.02" iyz="0" izz="0.0036"/>
    </inertial>
  </link>

  <joint name="left_hip_joint" type="revolute">
    <parent link="base_link"/>
    <child link="left_upper_leg"/>
    <origin xyz="0.1 0 -0.25" rpy="0 0 0"/>
    <axis xyz="0 1 0"/>
    <limit lower="-1.57" upper="1.57" effort="20" velocity="1"/>
  </joint>

  <link name="left_lower_leg">
    <visual>
      <geometry>
        <cylinder length="0.4" radius="0.05"/>
      </geometry>
      <material name="black"/>
    </visual>
    <collision>
      <geometry>
        <cylinder length="0.4" radius="0.05"/>
      </geometry>
    </collision>
    <inertial>
      <mass value="1.5"/>
      <inertia ixx="0.015" ixy="0" ixz="0" iyy="0.015" iyz="0" izz="0.0025"/>
    </inertial>
  </link>

  <joint name="left_knee_joint" type="revolute">
    <parent link="left_upper_leg"/>
    <child link="left_lower_leg"/>
    <origin xyz="0 0 -0.4" rpy="0 0 0"/>
    <axis xyz="0 1 0"/>
    <limit lower="0" upper="1.57" effort="20" velocity="1"/>
  </joint>

  <!-- Right Leg -->
  <link name="right_upper_leg">
    <visual>
      <geometry>
        <cylinder length="0.4" radius="0.06"/>
      </geometry>
      <material name="black"/>
    </visual>
    <collision>
      <geometry>
        <cylinder length="0.4" radius="0.06"/>
      </geometry>
    </collision>
    <inertial>
      <mass value="2.0"/>
      <inertia ixx="0.02" ixy="0" ixz="0" iyy="0.02" iyz="0" izz="0.0036"/>
    </inertial>
  </link>

  <joint name="right_hip_joint" type="revolute">
    <parent link="base_link"/>
    <child link="right_upper_leg"/>
    <origin xyz="-0.1 0 -0.25" rpy="0 0 0"/>
    <axis xyz="0 1 0"/>
    <limit lower="-1.57" upper="1.57" effort="20" velocity="1"/>
  </joint>

  <link name="right_lower_leg">
    <visual>
      <geometry>
        <cylinder length="0.4" radius="0.05"/>
      </geometry>
      <material name="black"/>
    </visual>
    <collision>
      <geometry>
        <cylinder length="0.4" radius="0.05"/>
      </geometry>
    </collision>
    <inertial>
      <mass value="1.5"/>
      <inertia ixx="0.015" ixy="0" ixz="0" iyy="0.015" iyz="0" izz="0.0025"/>
    </inertial>
  </link>

  <joint name="right_knee_joint" type="revolute">
    <parent link="right_upper_leg"/>
    <child link="right_lower_leg"/>
    <origin xyz="0 0 -0.4" rpy="0 0 0"/>
    <axis xyz="0 1 0"/>
    <limit lower="0" upper="1.57" effort="20" velocity="1"/>
  </joint>
</robot>